Workbook

Sheet Total
A1: Scope 1
B2: Combine
A3: Month | B3: 2022 | C3: 2023 | D3: 2024 | E3: 2025 | F3: 2026
B4: MT CO2 | C4: MT CO2 | D4: MT CO2 | E4: MT CO2 | F4: MT CO2
A5: Jan | B5: ='LPG 14kg'!C45+'LPG 50kg'!C45+Diesel!C45+Petrol!C45 -> 8.8990804 | C5: ='LPG 14kg'!D45+'LPG 50kg'!D45+Diesel!D45+Petrol!D45 -> 15.491 | D5: ='LPG 14kg'!E45+'LPG 50kg'!E45+Diesel!E45+Petrol!E45 -> 18.408 | E5: ='LPG 14kg'!F45+'LPG 50kg'!F45+Diesel!F45+Petrol!F45 -> 20.884 | F5: ='LPG 14kg'!G45+'LPG 50kg'!G45+Diesel!G45+Petrol!G45 -> 16.011
A6: Feb | B6: ='LPG 14kg'!C46+'LPG 50kg'!C46+Diesel!C46+Petrol!C46 -> 7.1051519 | C6: ='LPG 14kg'!D46+'LPG 50kg'!D46+Diesel!D46+Petrol!D46 -> 14.96 | D6: ='LPG 14kg'!E46+'LPG 50kg'!E46+Diesel!E46+Petrol!E46 -> 18.732 | E6: ='LPG 14kg'!F46+'LPG 50kg'!F46+Diesel!F46+Petrol!F46 -> 18.296 | F6: ='LPG 14kg'!G46+'LPG 50kg'!G46+Diesel!G46+Petrol!G46 -> 14.921
A7: Mar | B7: ='LPG 14kg'!C47+'LPG 50kg'!C47+Diesel!C47+Petrol!C47 -> 9.5998456 | C7: ='LPG 14kg'!D47+'LPG 50kg'!D47+Diesel!D47+Petrol!D47 -> 18.596 | D7: ='LPG 14kg'!E47+'LPG 50kg'!E47+Diesel!E47+Petrol!E47 -> 18.568 | E7: ='LPG 14kg'!F47+'LPG 50kg'!F47+Diesel!F47+Petrol!F47 -> 20.95 | F7: ='LPG 14kg'!G47+'LPG 50kg'!G47+Diesel!G47+Petrol!G47 -> 13.733
A8: Apr | B8: ='LPG 14kg'!C48+'LPG 50kg'!C48+Diesel!C48+Petrol!C48 -> 7.8184809 | C8: ='LPG 14kg'!D48+'LPG 50kg'!D48+Diesel!D48+Petrol!D48 -> 16.169 | D8: ='LPG 14kg'!E48+'LPG 50kg'!E48+Diesel!E48+Petrol!E48 -> 18.974 | E8: ='LPG 14kg'!F48+'LPG 50kg'!F48+Diesel!F48+Petrol!F48 -> 18.123 | F8: ='LPG 14kg'!G48+'LPG 50kg'!G48+Diesel!G48+Petrol!G48 -> 16.672
A9: May | B9: ='LPG 14kg'!C49+'LPG 50kg'!C49+Diesel!C49+Petrol!C49 -> 10.06247 | C9: ='LPG 14kg'!D49+'LPG 50kg'!D49+Diesel!D49+Petrol!D49 -> 21.433 | D9: ='LPG 14kg'!E49+'LPG 50kg'!E49+Diesel!E49+Petrol!E49 -> 19.867 | E9: ='LPG 14kg'!F49+'LPG 50kg'!F49+Diesel!F49+Petrol!F49 -> 19.552 | F9: ='LPG 14kg'!G49+'LPG 50kg'!G49+Diesel!G49+Petrol!G49 -> 16.782
A10: Jun | B10: ='LPG 14kg'!C50+'LPG 50kg'!C50+Diesel!C50+Petrol!C50 -> 9.5539168 | C10: ='LPG 14kg'!D50+'LPG 50kg'!D50+Diesel!D50+Petrol!D50 -> 18.187 | D10: ='LPG 14kg'!E50+'LPG 50kg'!E50+Diesel!E50+Petrol!E50 -> 22.929 | E10: ='LPG 14kg'!F50+'LPG 50kg'!F50+Diesel!F50+Petrol!F50 -> 18.646 | F10: ='LPG 14kg'!G50+'LPG 50kg'!G50+Diesel!G50+Petrol!G50 -> 17.796
A11: Jul | B11: ='LPG 14kg'!C51+'LPG 50kg'!C51+Diesel!C51+Petrol!C51 -> 10.274517 | C11: ='LPG 14kg'!D51+'LPG 50kg'!D51+Diesel!D51+Petrol!D51 -> 21.636 | D11: ='LPG 14kg'!E51+'LPG 50kg'!E51+Diesel!E51+Petrol!E51 -> 23.536 | E11: ='LPG 14kg'!F51+'LPG 50kg'!F51+Diesel!F51+Petrol!F51 -> 18.842 | F11: ='LPG 14kg'!G51+'LPG 50kg'!G51+Diesel!G51+Petrol!G51 -> 19.451
A12: Aug | B12: ='LPG 14kg'!C52+'LPG 50kg'!C52+Diesel!C52+Petrol!C52 -> 8.512192 | C12: ='LPG 14kg'!D52+'LPG 50kg'!D52+Diesel!D52+Petrol!D52 -> 23.838 | D12: ='LPG 14kg'!E52+'LPG 50kg'!E52+Diesel!E52+Petrol!E52 -> 24.964 | E12: ='LPG 14kg'!F52+'LPG 50kg'!F52+Diesel!F52+Petrol!F52 -> 14.741 | F12: ='LPG 14kg'!G52+'LPG 50kg'!G52+Diesel!G52+Petrol!G52 -> 0
A13: Sep | B13: ='LPG 14kg'!C53+'LPG 50kg'!C53+Diesel!C53+Petrol!C53 -> 11.473154 | C13: ='LPG 14kg'!D53+'LPG 50kg'!D53+Diesel!D53+Petrol!D53 -> 21.965 | D13: ='LPG 14kg'!E53+'LPG 50kg'!E53+Diesel!E53+Petrol!E53 -> 21.396 | E13: ='LPG 14kg'!F53+'LPG 50kg'!F53+Diesel!F53+Petrol!F53 -> 14.056 | F13: ='LPG 14kg'!G53+'LPG 50kg'!G53+Diesel!G53+Petrol!G53 -> 0
A14: Oct | B14: ='LPG 14kg'!C54+'LPG 50kg'!C54+Diesel!C54+Petrol!C54 -> 9.0755961 | C14: ='LPG 14kg'!D54+'LPG 50kg'!D54+Diesel!D54+Petrol!D54 -> 22.769 | D14: ='LPG 14kg'!E54+'LPG 50kg'!E54+Diesel!E54+Petrol!E54 -> 21.759 | E14: ='LPG 14kg'!F54+'LPG 50kg'!F54+Diesel!F54+Petrol!F54 -> 15.992 | F14: ='LPG 14kg'!G54+'LPG 50kg'!G54+Diesel!G54+Petrol!G54 -> 0
A15: Nov | B15: ='LPG 14kg'!C55+'LPG 50kg'!C55+Diesel!C55+Petrol!C55 -> 9.5140609 | C15: ='LPG 14kg'!D55+'LPG 50kg'!D55+Diesel!D55+Petrol!D55 -> 19.282 | D15: ='LPG 14kg'!E55+'LPG 50kg'!E55+Diesel!E55+Petrol!E55 -> 20.422 | E15: ='LPG 14kg'!F55+'LPG 50kg'!F55+Diesel!F55+Petrol!F55 -> 12.078 | F15: ='LPG 14kg'!G55+'LPG 50kg'!G55+Diesel!G55+Petrol!G55 -> 0
A16: Dec | B16: ='LPG 14kg'!C56+'LPG 50kg'!C56+Diesel!C56+Petrol!C56 -> 10.154403 | C16: ='LPG 14kg'!D56+'LPG 50kg'!D56+Diesel!D56+Petrol!D56 -> 18.645 | D16: ='LPG 14kg'!E56+'LPG 50kg'!E56+Diesel!E56+Petrol!E56 -> 18.786 | E16: ='LPG 14kg'!F56+'LPG 50kg'!F56+Diesel!F56+Petrol!F56 -> 12.809 | F16: ='LPG 14kg'!G56+'LPG 50kg'!G56+Diesel!G56+Petrol!G56 -> 0
A17: Total | B17: =SUM(B5:B16) -> 112.04287 | C17: =SUM(C5:C16) -> 232.971 | D17: =SUM(D5:D16) -> 248.341 | E17: =SUM(E5:E16) -> 204.969 | F17: =SUM(F5:F16) -> 115.366

Sheet LPG 14kg
A1: =RIGHT(CELL("filename",A1),LEN(CELL("filename",A1))-FIND("]",CELL("filename",A1))) -> LPG 14kg
A2: Quantity
C4: Combine | I4: Tago | N4: KIP
B5: Month | C5: 2022 | D5: 2023 | E5: 2024 | F5: 2025 | G5: 2026 | I5: 2022 | J5: 2023 | K5: 2024 | L5: 2025 | M5: 2026 | N5: 2022 | O5: 2023 | P5: 2024 | Q5: 2025 | R5: 2026
C6: QTY | D6: QTY | E6: QTY | F6: QTY | G6: QTY | I6: QTY | J6: QTY | K6: QTY | L6: QTY | M6: QTY | N6: QTY | O6: QTY | P6: QTY | Q6: QTY | R6: QTY
B7: Jan | C7: =I7+N7 -> 21 | D7: 38 | E7: 58 | F7: 61 | G7: 59 | I7: 21 | J7: =D7-O7 -> 25 | K7: =E7-P7 -> 37 | L7: =F7-Q7 -> 43 | M7: 28 | N7: 0 | O7: 13 | P7: 21 | Q7: 18 | R7: 31
B8: Feb | C8: =I8+N8 -> 22 | D8: 49 | E8: 54 | F8: 69 | G8: 49 | I8: 22 | J8: =D8-O8 -> 36 | K8: =E8-P8 -> 54 | L8: =F8-Q8 -> 31 | M8: 29 | N8: 0 | O8: 13 | P8: 0 | Q8: 38 | R8: 20
B9: Mar | C9: =I9+N9 -> 34 | D9: 65 | E9: 86 | F9: 66 | G9: =M9+R9 -> 42 | I9: 34 | J9: =D9-O9 -> 54 | K9: =E9-P9 -> 70 | L9: =F9-Q9 -> 31 | M9: 29 | N9: 0 | O9: 11 | P9: 16 | Q9: 35 | R9: 13
B10: Apr | C10: =I10+N10 -> 24 | D10: 60 | E10: 74 | F10: 76 | G10: =M10+R10 -> 62 | I10: 24 | J10: =D10-O10 -> 44 | K10: =E10-P10 -> 59 | L10: =F10-Q10 -> 57 | M10: 26 | N10: 0 | O10: 16 | P10: 15 | Q10: 19 | R10: 36
B11: May | C11: =I11+N11 -> 38 | D11: 99 | E11: 76 | F11: 91 | G11: =M11+R11 -> 48 | I11: 38 | J11: =D11-O11 -> 53 | K11: =E11-P11 -> 65 | L11: =F11-Q11 -> 60 | M11: 25 | N11: 0 | O11: 46 | P11: 11 | Q11: 31 | R11: 23
B12: Jun | C12: =I12+N12 -> 25 | D12: 71 | E12: 102 | F12: 65 | G12: =M12+R12 -> 73 | I12: 25 | J12: =D12-O12 -> 18 | K12: =E12-P12 -> 55 | L12: =F12-Q12 -> 34 | M12: 31 | N12: 0 | O12: 53 | P12: 47 | Q12: 31 | R12: 42
B13: Jul | C13: =I13+N13 -> 35 | D13: 67 | E13: 85 | F13: 66 | G13: =M13+R13 -> 55 | I13: 35 | J13: =D13-O13 -> 43 | K13: =E13-P13 -> 39 | L13: =F13-Q13 -> 44 | M13: 24 | N13: 0 | O13: 24 | P13: 46 | Q13: 22 | R13: 31
B14: Aug | C14: =I14+N14 -> 37 | D14: 163 | E14: 108 | F14: 51 | G14: =M14+R14 -> 0 | I14: 26 | J14: =D14-O14 -> 92 | K14: =E14-P14 -> 55 | L14: =F14-Q14 -> 20 | N14: 11 | O14: 71 | P14: 53 | Q14: 31
B15: Sep | C15: =I15+N15 -> 51 | D15: 104 | E15: 98 | F15: 62 | G15: =M15+R15 -> 0 | I15: 38 | J15: =D15-O15 -> 45 | K15: =E15-P15 -> 64 | L15: =F15-Q15 -> 31 | N15: 13 | O15: 59 | P15: 34 | Q15: 31
B16: Oct | C16: =I16+N16 -> 26 | D16: 75 | E16: 81 | F16: 44 | G16: =M16+R16 -> 0 | I16: 10 | J16: =D16-O16 -> 37 | K16: =E16-P16 -> 47 | L16: =F16-Q16 -> 31 | N16: 16 | O16: 38 | P16: 34 | Q16: 13
B17: Nov | C17: =I17+N17 -> 48 | D17: 73 | E17: 63 | F17: 44 | G17: =M17+R17 -> 0 | I17: 34 | J17: =D17-O17 -> 47 | K17: =E17-P17 -> 36 | L17: =F17-Q17 -> 34 | N17: 14 | O17: 26 | P17: 27 | Q17: 10
B18: Dec | C18: =I18+N18 -> 57 | D18: 78 | E18: 78 | F18: =L18+Q18 -> 47 | G18: =M18+R18 -> 0 | I18: 39 | J18: =D18-O18 -> 58 | K18: =E18-P18 -> 45 | L18: 35 | N18: 18 | O18: 20 | P18: 33 | Q18: 12
B19: Total | C19: =SUM(C7:C18) -> 418 | D19: =SUM(D7:D18) -> 942 | E19: =SUM(E7:E18) -> 963 | F19: =SUM(F7:F18) -> 742 | G19: =SUM(G7:G18) -> 388 | I19: =SUM(I7:I18) -> 346 | J19: =SUM(J7:J18) -> 552 | K19: =SUM(K7:K18) -> 626 | L19: =SUM(L7:L18) -> 451 | M19: =SUM(M7:M18) -> 192 | N19: =SUM(N7:N18) -> 72 | O19: =SUM(O7:O18) -> 390 | P19: =SUM(P7:P18) -> 337 | ... R19: =SUM(R7:R18) -> 196
A21: Weight
C23: Combine | I23: Tago | N23: KIP
B24: Month | C24: 2022 | D24: 2023 | E24: 2024 | F24: 2025 | G24: 2026 | I24: 2022 | J24: 2023 | K24: 2024 | L24: 2025 | M24: 2026 | N24: 2022 | O24: 2023 | P24: 2024 | Q24: 2025 | R24: 2026 | T24: ROUND(IF(C73="","",INDEX('\\192.168.10.203\Esh\08 GHG PROJECT\GHG INVENTORY\CARBON FOOTPRINT DATA\SCOPE 1\[GHG DATA_SCOPE 1.xlsx]LPG 14kg'!C38:G38,MATCH(C73,'\\192.168.10.203\Esh\08 GHG PROJECT\GHG INVENTORY\CARBON FOOTPRINT DATA\SCOPE 1\[GHG DATA_SCOPE 1.xlsx]LPG 14kg'!C24:G24,0))+INDEX('\\192.168.10.203\Esh\08 GHG PROJECT\GHG INVENTORY\CARBON FOOTPRINT DATA\SCOPE 1\[GHG DATA_SCOPE 1.xlsx]LPG 50kg'!C38:G38,MATCH(C73,'\\192.168.10.203\Esh\08 GHG PROJECT\GHG INVENTORY\CARBON FOOTPRINT DATA\SCOPE 1\[GHG DATA_SCOPE 1.xlsx]LPG 50kg'!C24:G24,0))),3)
C25: KG | D25: KG | E25: KG | F25: KG | G25: KG | I25: KG | J25: KG | K25: KG | L25: KG | M25: KG | N25: KG | O25: KG | P25: KG | Q25: KG | R25: KG
B26: Jan | C26: =C7*14 -> 294 | D26: =D7*14 -> 532 | E26: =E7*14 -> 812 | F26: =F7*14 -> 854 | G26: =G7*14 -> 826 | I26: =I7*14 -> 294 | J26: =J7*14 -> 350 | K26: =K7*14 -> 518 | L26: =L7*14 -> 602 | M26: =M7*14 -> 392 | N26: =N7*14 -> 0 | O26: =O7*14 -> 182 | P26: =P7*14 -> 294 | ... R26: =R7*14 -> 434
B27: Feb | C27: =C8*14 -> 308 | D27: =D8*14 -> 686 | E27: =E8*14 -> 756 | F27: =F8*14 -> 966 | G27: =G8*14 -> 686 | I27: =I8*14 -> 308 | J27: =J8*14 -> 504 | K27: =K8*14 -> 756 | L27: =L8*14 -> 434 | M27: =M8*14 -> 406 | N27: =N8*14 -> 0 | O27: =O8*14 -> 182 | P27: =P8*14 -> 0 | ... R27: =R8*14 -> 280
B28: Mar | C28: =C9*14 -> 476 | D28: =D9*14 -> 910 | E28: =E9*14 -> 1204 | F28: =F9*14 -> 924 | G28: =G9*14 -> 588 | I28: =I9*14 -> 476 | J28: =J9*14 -> 756 | K28: =K9*14 -> 980 | L28: =L9*14 -> 434 | M28: =M9*14 -> 406 | N28: =N9*14 -> 0 | O28: =O9*14 -> 154 | P28: =P9*14 -> 224 | ... R28: =R9*14 -> 182
B29: Apr | C29: =C10*14 -> 336 | D29: =D10*14 -> 840 | E29: =E10*14 -> 1036 | F29: =F10*14 -> 1064 | G29: =G10*14 -> 868 | I29: =I10*14 -> 336 | J29: =J10*14 -> 616 | K29: =K10*14 -> 826 | L29: =L10*14 -> 798 | M29: =M10*14 -> 364 | N29: =N10*14 -> 0 | O29: =O10*14 -> 224 | P29: =P10*14 -> 210 | ... R29: =R10*14 -> 504
B30: May | C30: =C11*14 -> 532 | D30: =D11*14 -> 1386 | E30: =E11*14 -> 1064 | F30: =F11*14 -> 1274 | G30: =G11*14 -> 672 | I30: =I11*14 -> 532 | J30: =J11*14 -> 742 | K30: =K11*14 -> 910 | L30: =L11*14 -> 840 | M30: =M11*14 -> 350 | N30: =N11*14 -> 0 | O30: =O11*14 -> 644 | P30: =P11*14 -> 154 | ... R30: =R11*14 -> 322
B31: Jun | C31: =C12*14 -> 350 | D31: =D12*14 -> 994 | E31: =E12*14 -> 1428 | F31: =F12*14 -> 910 | G31: =G12*14 -> 1022 | I31: =I12*14 -> 350 | J31: =J12*14 -> 252 | K31: =K12*14 -> 770 | L31: =L12*14 -> 476 | M31: =M12*14 -> 434 | N31: =N12*14 -> 0 | O31: =O12*14 -> 742 | P31: =P12*14 -> 658 | ... R31: =R12*14 -> 588
B32: Jul | C32: =C13*14 -> 490 | D32: =D13*14 -> 938 | E32: =E13*14 -> 1190 | F32: =F13*14 -> 924 | G32: =G13*14 -> 770 | I32: =I13*14 -> 490 | J32: =J13*14 -> 602 | K32: =K13*14 -> 546 | L32: =L13*14 -> 616 | M32: =M13*14 -> 336 | N32: =N13*14 -> 0 | O32: =O13*14 -> 336 | P32: =P13*14 -> 644 | ... R32: =R13*14 -> 434
B33: Aug | C33: =C14*14 -> 518 | D33: =D14*14 -> 2282 | E33: =E14*14 -> 1512 | F33: =F14*14 -> 714 | G33: =G14*14 -> 0 | I33: =I14*14 -> 364 | J33: =J14*14 -> 1288 | K33: =K14*14 -> 770 | L33: =L14*14 -> 280 | M33: =M14*14 -> 0 | N33: =N14*14 -> 154 | O33: =O14*14 -> 994 | P33: =P14*14 -> 742 | ... R33: =R14*14 -> 0
B34: Sep | C34: =C15*14 -> 714 | D34: =D15*14 -> 1456 | E34: =E15*14 -> 1372 | F34: =F15*14 -> 868 | G34: =G15*14 -> 0 | I34: =I15*14 -> 532 | J34: =J15*14 -> 630 | K34: =K15*14 -> 896 | L34: =L15*14 -> 434 | M34: =M15*14 -> 0 | N34: =N15*14 -> 182 | O34: =O15*14 -> 826 | P34: =P15*14 -> 476 | ... R34: =R15*14 -> 0
B35: Oct | C35: =C16*14 -> 364 | D35: =D16*14 -> 1050 | E35: =E16*14 -> 1134 | F35: =F16*14 -> 616 | G35: =G16*14 -> 0 | I35: =I16*14 -> 140 | J35: =J16*14 -> 518 | K35: =K16*14 -> 658 | L35: =L16*14 -> 434 | M35: =M16*14 -> 0 | N35: =N16*14 -> 224 | O35: =O16*14 -> 532 | P35: =P16*14 -> 476 | ... R35: =R16*14 -> 0
B36: Nov | C36: =C17*14 -> 672 | D36: =D17*14 -> 1022 | E36: =E17*14 -> 882 | F36: =F17*14 -> 616 | G36: =G17*14 -> 0 | I36: =I17*14 -> 476 | J36: =J17*14 -> 658 | K36: =K17*14 -> 504 | L36: =L17*14 -> 476 | M36: =M17*14 -> 0 | N36: =N17*14 -> 196 | O36: =O17*14 -> 364 | P36: =P17*14 -> 378 | ... R36: =R17*14 -> 0
B37: Dec | C37: =C18*14 -> 798 | D37: =D18*14 -> 1092 | E37: =E18*14 -> 1092 | F37: =F18*14 -> 658 | G37: =G18*14 -> 0 | I37: =I18*14 -> 546 | J37: =J18*14 -> 812 | K37: =K18*14 -> 630 | L37: =L18*14 -> 490 | M37: =M18*14 -> 0 | N37: =N18*14 -> 252 | O37: =O18*14 -> 280 | P37: =P18*14 -> 462 | ... R37: =R18*14 -> 0
B38: Total | C38: =SUM(C26:C37) -> 5852 | D38: =SUM(D26:D37) -> 13188 | E38: =SUM(E26:E37) -> 13482 | F38: =SUM(F26:F37) -> 10388 | G38: =SUM(G26:G37) -> 5432 | I38: =SUM(I26:I37) -> 4844 | J38: =SUM(J26:J37) -> 7728 | K38: =SUM(K26:K37) -> 8764 | L38: =SUM(L26:L37) -> 6314 | M38: =SUM(M26:M37) -> 2688 | N38: =SUM(N26:N37) -> 1008 | O38: =SUM(O26:O37) -> 5460 | P38: =SUM(P26:P37) -> 4718 | ... R38: =SUM(R26:R37) -> 2744
A40: Emmision
C42: Combine | I42: Tago | N42: KIP
B43: Month | C43: 2022 | D43: 2023 | E43: 2024 | F43: 2025 | G43: 2026 | I43: 2022 | J43: 2023 | K43: 2024 | L43: 2025 | M43: 2026 | N43: 2022 | O43: 2023 | P43: 2024 | Q43: 2025 | R43: 2026
C44: MT CO2 | D44: MT CO2 | E44: MT CO2 | F44: MT CO2 | G44: MT CO2 | I44: MT CO2 | J44: MT CO2 | K44: MT CO2 | L44: MT CO2 | M44: MT CO2 | N44: MT CO1 | O44: MT CO2 | P44: MT CO2 | Q44: MT CO2 | R44: MT CO2
B45: Jan | C45: =C26*1.49/1000 -> 0.43806 | D45: =ROUND(D26*1.49/1000,3) -> 0.793 | E45: =ROUND(E26*1.49/1000,3) -> 1.21 | F45: =ROUND(F26*1.49/1000,3) -> 1.272 | G45: =ROUND(G26*1.49/1000,3) -> 1.231 | I45: =I26*1.49/1000 -> 0.43806 | J45: =J26*1.49/1000 -> 0.5215 | K45: =K26*1.49/1000 -> 0.77182 | L45: =L26*1.49/1000 -> 0.89698 | M45: =M26*1.49/1000 -> 0.58408 | N45: =N26*1.49/1000 -> 0 | O45: =O26*1.49/1000 -> 0.27118 | P45: =P26*1.49/1000 -> 0.43806 | ... R45: =R26*1.49/1000 -> 0.64666
...

Sheet LPG 50kg
A1: =RIGHT(CELL("filename",A1),LEN(CELL("filename",A1))-FIND("]",CELL("filename",A1))) -> LPG 50kg
A2: Quantity
C4: Tago
B5: Month | C5: 2022 | D5: 2023 | E5: 2024 | F5: 2025 | G5: 2026
C6: QTY | D6: QTY | E6: QTY | F6: QTY | G6: QTY
B7: Jan | C7: 18 | D7: 24 | E7: 36 | F7: 42 | G7: 24
B8: Feb | C8: 18 | D8: 6 | E8: 42 | F8: 24 | G8: 30
B9: Mar | C9: 24 | D9: 24 | E9: 30 | F9: 12 | G9: 30
B10: Apr | C10: 6 | D10: 18 | E10: 36 | F10: 18 | G10: 30
B11: May | C11: 24 | D11: 30 | E11: 42 | F11: 24 | G11: 30
B12: Jun | C12: 24 | D12: 18 | E12: 48 | F12: 18 | G12: 48
B13: Jul | C13: 24 | D13: 48 | E13: 30 | F13: 18 | G13: 36
B14: Aug | C14: 0 | D14: 66 | E14: 30 | F14: 12
B15: Sep | C15: 36 | D15: 47 | E15: 24 | F15: 18
B16: Oct | C16: 12 | D16: 66 | E16: 24 | F16: 18
B17: Nov | C17: 18 | D17: 42 | E17: 30 | F17: 12
B18: Dec | C18: 24 | D18: 54 | E18: 24 | F18: 12
B19: Total | C19: =SUM(C7:C18) -> 228 | D19: =SUM(D7:D18) -> 443 | E19: =SUM(E7:E18) -> 396 | F19: =SUM(F7:F18) -> 228 | G19: =SUM(G7:G18) -> 228
A21: Weight
C23: Tago
B24: Month | C24: 2022 | D24: 2023 | E24: 2024 | F24: 2025 | G24: 2026
C25: KG | D25: KG | E25: KG | F25: KG | G25: KG
B26: Jan | C26: =C7*50 -> 900 | D26: =D7*50 -> 1200 | E26: =E7*50 -> 1800 | F26: =F7*50 -> 2100 | G26: =G7*50 -> 1200
B27: Feb | C27: =C8*50 -> 900 | D27: =D8*50 -> 300 | E27: =E8*50 -> 2100 | F27: =F8*50 -> 1200 | G27: =G8*50 -> 1500
B28: Mar | C28: =C9*50 -> 1200 | D28: =D9*50 -> 1200 | E28: =E9*50 -> 1500 | F28: =F9*50 -> 600 | G28: =G9*50 -> 1500
B29: Apr | C29: =C10*50 -> 300 | D29: =D10*50 -> 900 | E29: =E10*50 -> 1800 | F29: =F10*50 -> 900 | G29: =G10*50 -> 1500
B30: May | C30: =C11*50 -> 1200 | D30: =D11*50 -> 1500 | E30: =E11*50 -> 2100 | F30: =F11*50 -> 1200 | G30: =G11*50 -> 1500
B31: Jun | C31: =C12*50 -> 1200 | D31: =D12*50 -> 900 | E31: =E12*50 -> 2400 | F31: =F12*50 -> 900 | G31: =G12*50 -> 2400
B32: Jul | C32: =C13*50 -> 1200 | D32: =D13*50 -> 2400 | E32: =E13*50 -> 1500 | F32: =F13*50 -> 900 | G32: =G13*50 -> 1800
B33: Aug | C33: =C14*50 -> 0 | D33: =D14*50 -> 3300 | E33: =E14*50 -> 1500 | F33: =F14*50 -> 600 | G33: =G14*50 -> 0
B34: Sep | C34: =C15*50 -> 1800 | D34: =D15*50 -> 2350 | E34: =E15*50 -> 1200 | F34: =F15*50 -> 900 | G34: =G15*50 -> 0
B35: Oct | C35: =C16*50 -> 600 | D35: =D16*50 -> 3300 | E35: =E16*50 -> 1200 | F35: =F16*50 -> 900 | G35: =G16*50 -> 0
B36: Nov | C36: =C17*50 -> 900 | D36: =D17*50 -> 2100 | E36: =E17*50 -> 1500 | F36: =F17*50 -> 600 | G36: =G17*50 -> 0
B37: Dec | C37: =C18*50 -> 1200 | D37: =D18*50 -> 2700 | E37: =E18*50 -> 1200 | F37: =F18*50 -> 600 | G37: =G18*50 -> 0
B38: Total | C38: =SUM(C26:C37) -> 11400 | D38: =SUM(D26:D37) -> 22150 | E38: =SUM(E26:E37) -> 19800 | F38: =SUM(F26:F37) -> 11400 | G38: =SUM(G26:G37) -> 11400
A40: Emmision
C42: Tago
B43: Month | C43: 2022 | D43: 2023 | E43: 2024 | F43: 2025 | G43: 2026
C44: MT CO2 | D44: MT CO2 | E44: MT CO2 | F44: MT CO2 | G44: MT CO2
B45: Jan | C45: =C26*1.49/1000 -> 1.341 | D45: =ROUND(D26*1.49/1000,3) -> 1.788 | E45: =ROUND(E26*1.49/1000,3) -> 2.682 | F45: =ROUND(F26*1.49/1000,3) -> 3.129 | G45: =ROUND(G26*1.49/1000,3) -> 1.788
...

Sheet Diesel
A1: =RIGHT(CELL("filename",A1),LEN(CELL("filename",A1))-FIND("]",CELL("filename",A1))) -> Diesel
A2: Litre
C4: Tago
B5: Month | C5: 2022 | D5: 2023 | E5: 2024 | F5: 2025 | G5: 2026
C6: L | D6: L | E6: L | F6: L | G6: L
B7: Jan | C7: 2890.3395 | D7: 2942.1697 | E7: 3272.907 | F7: 4610.629 | G7: 3569.1941
B8: Feb | C8: 2143.4279 | D8: 3357.5712 | E8: 3225.4465 | F8: 4207.0283 | G8: 3057.1355
B9: Mar | C9: 2888.4512 | D9: 3837.7208 | E9: 3525.8884 | F9: 5343.649 | G9: 3064.4513
B10: Apr | C10: 2759.9721 | D10: 3550.2955 | E10: 3239.1953 | F10: 4343.8255 | G10: 3598.4795
B11: May | C11: 3027.7256 | D11: 4252.0697 | E11: 3521.9721 | F11: 4438.1963 | G11: =3344.589+366.848 -> 3711.437
B12: Jun | C12: 2910.6233 | D12: 3640.4213 | E12: 4684.0266 | F12: 4533.9135 | G12: 3353.068
B13: Jul | C13: 3094.4791 | D13: 3946.4301 | E13: 5528.3951 | F13: 4080.3315 | G13: =3407.893+459.201 -> 3867.094
B14: Aug | C14: 3109.6186 | D14: 3783.2718 | E14: 5764.1517 | F14: 2799.8429
B15: Sep | C15: 3155.586 | D15: 3745.9814 | E15: 5210.7742 | F15: 2602.1054
B16: Oct | C16: 3105.2326 | D16: 3705.8 | E16: 5097.4316 | F16: 3095.7687
B17: Nov | C17: 2908.0558 | D17: 3329.9778 | E17: 4795.3555 | F17: 2610.0609
B18: Dec | C18: 2905.4279 | D18: 2965.6061 | E18: 4566.7647 | F18: 2814.2053
B19: Total | C19: =SUM(C7:C18) -> 34898.94 | D19: =SUM(D7:D18) -> 43057.315 | E19: =SUM(E7:E18) -> 52432.309 | F19: =SUM(F7:F18) -> 45479.556 | G19: =SUM(G7:G18) -> 24220.859
A21: Weight
C23: Tago
B24: Month | C24: 2022 | D24: 2023 | E24: 2024 | F24: 2025 | G24: 2026
C25: KG | D25: KG | E25: KG | F25: KG | G25: KG
B26: Jan | C26: =C7*0.84 -> 2427.8852 | D26: =ROUND(D7*0.84,3) -> 2471.423 | E26: =ROUND(E7*0.84,3) -> 2749.242 | F26: =ROUND(F7*0.84,3) -> 3872.928 | G26: =ROUND(G7*0.84,3) -> 2998.123 | O26: 2025 | P26: 3872.928 | Q26: 3533.904 | R26: 4488.665 | S26: 3648.813 | T26: 3728.085 | U26: 3808.487 | V26: 3427.478 | W26: 2351.868 | X26: 2185.769 | Y26: 2600.446 | Z26: 2192.451 | AA26: 2363.932
B27: Feb | C27: =C8*0.84 -> 1800.4794 | D27: =ROUND(D8*0.84,3) -> 2820.36 | E27: =ROUND(E8*0.84,3) -> 2709.375 | F27: =ROUND(F8*0.84,3) -> 3533.904 | G27: =ROUND(G8*0.84,3) -> 2567.994 | O27: 2026 | P27: 2998.123 | Q27: 2567.994 | R27: 2574.139 | S27: 3022.723 | T27: 3117.607 | U27: 2816.577 | V27: 3248.359 | W27: 0 | X27: 0 | Y27: 0 | Z27: 0 | AA27: 0
B28: Mar | C28: =C9*0.84 -> 2426.299 | D28: =ROUND(D9*0.84,3) -> 3223.685 | E28: =ROUND(E9*0.84,3) -> 2961.746 | F28: =ROUND(F9*0.84,3) -> 4488.665 | G28: =ROUND(G9*0.84,3) -> 2574.139
B29: Apr | C29: =C10*0.84 -> 2318.3766 | D29: =ROUND(D10*0.84,3) -> 2982.248 | E29: =ROUND(E10*0.84,3) -> 2720.924 | F29: =ROUND(F10*0.84,3) -> 3648.813 | G29: =ROUND(G10*0.84,3) -> 3022.723
B30: May | C30: =C11*0.84 -> 2543.2895 | D30: =ROUND(D11*0.84,3) -> 3571.739 | E30: =ROUND(E11*0.84,3) -> 2958.457 | F30: =ROUND(F11*0.84,3) -> 3728.085 | G30: =ROUND(G11*0.84,3) -> 3117.607
B31: Jun | C31: =C12*0.84 -> 2444.9235 | D31: =ROUND(D12*0.84,3) -> 3057.954 | E31: =ROUND(E12*0.84,3) -> 3934.582 | F31: =ROUND(F12*0.84,3) -> 3808.487 | G31: =ROUND(G12*0.84,3) -> 2816.577
B32: Jul | C32: =C13*0.84 -> 2599.3624 | D32: =ROUND(D13*0.84,3) -> 3315.001 | E32: =ROUND(E13*0.84,3) -> 4643.852 | F32: =ROUND(F13*0.84,3) -> 3427.478 | G32: =ROUND(G13*0.84,3) -> 3248.359
B33: Aug | C33: =C14*0.84 -> 2612.0796 | D33: =ROUND(D14*0.84,3) -> 3177.948 | E33: =ROUND(E14*0.84,3) -> 4841.887 | F33: =ROUND(F14*0.84,3) -> 2351.868 | G33: =ROUND(G14*0.84,3) -> 0
B34: Sep | C34: =C15*0.84 -> 2650.6923 | D34: =ROUND(D15*0.84,3) -> 3146.624 | E34: =ROUND(E15*0.84,3) -> 4377.05 | F34: =ROUND(F15*0.84,3) -> 2185.769 | G34: =ROUND(G15*0.84,3) -> 0
B35: Oct | C35: =C16*0.84 -> 2608.3953 | D35: =ROUND(D16*0.84,3) -> 3112.872 | E35: =ROUND(E16*0.84,3) -> 4281.843 | F35: =ROUND(F16*0.84,3) -> 2600.446 | G35: =ROUND(G16*0.84,3) -> 0
B36: Nov | C36: =C17*0.84 -> 2442.7669 | D36: =ROUND(D17*0.84,3) -> 2797.181 | E36: =ROUND(E17*0.84,3) -> 4028.099 | F36: =ROUND(F17*0.84,3) -> 2192.451 | G36: =ROUND(G17*0.84,3) -> 0
B37: Dec | C37: =C18*0.84 -> 2440.5594 | D37: =ROUND(D18*0.84,3) -> 2491.109 | E37: =ROUND(E18*0.84,3) -> 3836.082 | F37: =ROUND(F18*0.84,3) -> 2363.932 | G37: =ROUND(G18*0.84,3) -> 0
B38: Total | C38: =SUM(C26:C37) -> 29315.109 | D38: =SUM(D26:D37) -> 36168.144 | E38: 34132.15 | F38: =SUM(F26:F37) -> 38202.826 | G38: =SUM(G26:G37) -> 20345.522
A40: Emmision
C42: Tago
B43: Month | C43: 2022 | D43: 2023 | E43: 2024 | F43: 2025 | G43: 2026
C44: MT CO2 | D44: MT CO2 | E44: MT CO2 | F44: MT CO2 | G44: MT CO2
B45: Jan | C45: =C26*2.653/1000 -> 6.4411795 | D45: =ROUND(D26*2.653/1000,3) -> 6.557 | E45: =ROUND(E26*2.653/1000,3) -> 7.294 | F45: =ROUND(F26*2.653/1000,3) -> 10.275 | G45: =ROUND(G26*2.70533/1000,3) -> 8.111
...

Sheet Petrol
A1: =RIGHT(CELL("filename",A1),LEN(CELL("filename",A1))-FIND("]",CELL("filename",A1))) -> Petrol
A2: Litre
C4: Tago
B5: Month | C5: 2022* | D5: 2023 | E5: 2024 | F5: 2025 | G5: 2026
C6: L | D6: L | E6: L | F6: L | G6: L
B7: Jan | C7: 373.60537 | D7: 3683.1171 | E7: 4186.8537 | F7: 3598.81 | G7: 2781.6
B8: Feb | C8: 290.89707 | D8: 3483.6585 | E8: 4225.6293 | F8: 3301.12 | G8: 2688.3
B9: Mar | C9: 366.33707 | D9: 4000.2341 | E9: 3873 | F9: 3925.21 | G9: 2084.84
B10: Apr | C10: 396.36098 | D10: 3283.322 | E10: 4364.878 | F10: 3198.54 | G10: 2830.7
B11: May | C11: 404.20634 | D11: 4438.8293 | E11: 4234.1512 | F11: 3293.69 | G11: =529.45+2384.009 -> 2913.459
B12: Jun | C12: 417.19024 | D12: 4204.1122 | E12: 3934.5951 | F12: 3217.4 | G12: 2893.38
B13: Jul | C13: 473.47756 | D13: 4560.6683 | E13: 4178.7512 | F13: 3904.64 | G13: =3307.689+586.701 -> 3894.39
B14: Aug | C14: 446.07854 | D14: 4110.1073 | E14: 4422.9122 | F14: 3658.67
B15: Sep | C15: 382.50293 | D15: 4606.3561 | E15: 3450.5366 | F15: 3139.66
B16: Oct | C16: 395.79707 | D16: 4654.639 | E16: 4012.4049 | F16: 3816.82
B17: Nov | C17: 380.36341 | D17: 4178.9268 | E17: 3586.2341 | F17: 2470.45
B18: Dec | C18: 386.66976 | D18: 3702.0634 | E18: 3010.7317 | F18: 2587.28
B19: Total | C19: =SUM(C7:C18) -> 4713.4863 | D19: =SUM(D7:D18) -> 48906.034 | E19: =SUM(E7:E18) -> 47480.678 | F19: =SUM(F7:F18) -> 40112.29 | G19: =SUM(G7:G18) -> 20086.669
A21: Weight
C23: Tago
B24: Month | C24: 2022* | D24: 2023 | E24: 2024 | F24: 2025 | G24: 2026
C25: KG | D25: KG | E25: KG | F25: KG | G25: KG
B26: Jan | C26: =C7*0.79 -> 295.14824 | D26: =ROUND((D7*0.75),3) -> 2762.338 | E26: =ROUND((E7*0.75),3) -> 3140.14 | F26: =ROUND((F7*0.75),3) -> 2699.108 | G26: =ROUND((G7*0.75),3) -> 2086.2 | J26: 2025 | K26: 2699.108 | L26: 2475.84 | M26: 2943.908 | N26: 2398.905 | O26: 2470.268 | P26: 2413.05 | Q26: 2928.48 | R26: 2744.003 | S26: 2354.745 | T26: 2862.615 | U26: 1852.838 | V26: 1940.46
B27: Feb | C27: =C8*0.79 -> 229.80869 | D27: =ROUND((D8*0.75),3) -> 2612.744 | E27: =ROUND((E8*0.75),3) -> 3169.222 | F27: =ROUND((F8*0.75),3) -> 2475.84 | G27: =ROUND((G8*0.75),3) -> 2016.225 | J27: 2026 | K27: 2086.2 | L27: 2016.225 | M27: 1563.63 | N27: 2123.025 | O27: 2185.094 | P27: 2170.035 | Q27: 2920.793 | R27: 0 | S27: 0 | T27: 0 | U27: 0 | V27: 0
B28: Mar | C28: =C9*0.79 -> 289.40629 | D28: =ROUND((D9*0.75),3) -> 3000.176 | E28: =ROUND((E9*0.75),3) -> 2904.75 | F28: =ROUND((F9*0.75),3) -> 2943.908 | G28: =ROUND((G9*0.75),3) -> 1563.63
B29: Apr | C29: =C10*0.79 -> 313.12517 | D29: =ROUND((D10*0.75),3) -> 2462.491 | E29: =ROUND((E10*0.75),3) -> 3273.659 | F29: =ROUND((F10*0.75),3) -> 2398.905 | G29: =ROUND((G10*0.75),3) -> 2123.025
B30: May | C30: =C11*0.79 -> 319.32301 | D30: =ROUND((D11*0.75),3) -> 3329.122 | E30: =ROUND((E11*0.75),3) -> 3175.613 | F30: =ROUND((F11*0.75),3) -> 2470.268 | G30: =ROUND((G11*0.75),3) -> 2185.094
B31: Jun | C31: =C12*0.79 -> 329.58029 | D31: =ROUND((D12*0.75),3) -> 3153.084 | E31: =ROUND((E12*0.75),3) -> 2950.946 | F31: =ROUND((F12*0.75),3) -> 2413.05 | G31: =ROUND((G12*0.75),3) -> 2170.035
B32: Jul | C32: =C13*0.79 -> 374.04727 | D32: =ROUND((D13*0.75),3) -> 3420.501 | E32: =ROUND((E13*0.75),3) -> 3134.063 | F32: =ROUND((F13*0.75),3) -> 2928.48 | G32: =ROUND((G13*0.75),3) -> 2920.793 | K32: GHG Emission | L32: Parameter | M32: Jan | O32: Feb | Q32: Mar | S32: Apr | U32: May | W32: Jun | Y32: Jul | AA32: Aug | AC32: Sep | AE32: Oct | AG32: Nov | AI32: Dec
B33: Aug | C33: =C14*0.79 -> 352.40204 | D33: =ROUND((D14*0.75),3) -> 3082.58 | E33: =ROUND((E14*0.75),3) -> 3317.184 | F33: =ROUND((F14*0.75),3) -> 2744.003 | G33: =ROUND((G14*0.75),3) -> 0 | M33: 2025 | N33: 2026 | O33: 2025 | P33: 2026 | Q33: 2025 | R33: 2026 | S33: 2025 | T33: 2026 | U33: 2025 | V33: 2026 | W33: 2025 | X33: 2026 | Y33: 2025 | Z33: 2026 | AA33: 2025 | AB33: 2026 | AC33: 2025 | AD33: 2026 | AE33: 2025 | AF33: 2026 | AG33: 2025 | AH33: 2026 | AI33: 2025 | AJ33: 2026
B34: Sep | C34: =C15*0.79 -> 302.17731 | D34: =ROUND((D15*0.75),3) -> 3454.767 | E34: =ROUND((E15*0.75),3) -> 2587.902 | F34: =ROUND((F15*0.75),3) -> 2354.745 | G34: =ROUND((G15*0.75),3) -> 0 | K34: SCOPE 1 EMISSION | L34: Diesel (kg) | M34: 3872.93 | N34: 2998.12 | O34: 3533.9 | P34: 2567.99 | Q34: 4488.67 | R34: 2574.14 | S34: 3648.81 | T34: 3022.72 | U34: 3728.09 | V34: 3117.61 | W34: 3808.49 | X34: 2816.58 | Y34: 3427.48 | Z34: 3248.36 | AA34: 2351.87 | AB34: 0 | AC34: 2185.77 | AD34: 0 | AE34: 2600.45 | AF34: 0 | AG34: 2192.45 | AH34: 0 | AI34: 2363.93 | AJ34: 0
B35: Oct | C35: =C16*0.79 -> 312.67969 | D35: =ROUND((D16*0.75),3) -> 3490.979 | E35: =ROUND((E16*0.75),3) -> 3009.304 | F35: =ROUND((F16*0.75),3) -> 2862.615 | G35: =ROUND((G16*0.75),3) -> 0 | K35: SCOPE 1 EMISSION | L35: Petrol (kg) | M35: 2699.11 | N35: 2086.2 | O35: 2475.84 | P35: 2016.23 | Q35: 2943.91 | R35: 1563.63 | S35: 2398.91 | T35: 2123.03 | U35: 2470.27 | V35: 2185.09 | W35: 2413.05 | X35: 2170.04 | Y35: 2928.48 | Z35: 2920.79 | AA35: 2744 | AB35: 0 | AC35: 2354.75 | AD35: 0 | AE35: 2862.62 | AF35: 0 | AG35: 1852.84 | AH35: 0 | AI35: 1940.46 | AJ35: 0
B36: Nov | C36: =C17*0.79 -> 300.4871 | D36: =ROUND((D17*0.75),3) -> 3134.195 | E36: =ROUND((E17*0.75),3) -> 2689.676 | F36: =ROUND((F17*0.75),3) -> 1852.838 | G36: =ROUND((G17*0.75),3) -> 0
B37: Dec | C37: =C18*0.79 -> 305.46911 | D37: =ROUND((D18*0.75),3) -> 2776.548 | E37: =ROUND((E18*0.75),3) -> 2258.049 | F37: =ROUND((F18*0.75),3) -> 1940.46 | G37: =ROUND((G18*0.75),3) -> 0
B38: Total | C38: =C19*0.79 -> 3723.6542 | D38: =D19*0.79 -> 38635.767 | E38: =E19*0.79 -> 37509.736 | F38: =F19*0.79 -> 31688.709 | G38: =G19*0.79 -> 15868.469
A40: Emmision
C42: Tago
B43: Month | C43: 2022 | D43: 2023 | E43: 2024 | F43: 2025 | G43: 2026
C44: MT CO2 | D44: MT CO2 | E44: MT CO2 | F44: MT CO2 | G44: MT CO2
B45: Jan | C45: =C26*2.3/1000 -> 0.67884095 | D45: =ROUND(D26*2.3/1000,3) -> 6.353 | E45: =ROUND(E26*2.3/1000,3) -> 7.222 | F45: =ROUND(F26*2.3/1000,3) -> 6.208 | G45: =ROUND(G26*2.33969/1000,3) -> 4.881
...
